2020-02-25 07:05:23,796 INFO https://datos.cdmx.gob.mx/explore/dataset/fotocivicas/download/?format=csv&timezone=America/Mexico_City&lang=es&use_labels_for_header=true&csv_separator=%2C
2020-02-25 07:05:29,915 ERROR 
------------------------------
ERROR
Traceback (most recent call last):
  File "download_files.py", line 30, in download
    filedata = urllib2.urlopen(url)
  File "/usr/lib/python2.7/urllib2.py", line 127, in urlopen
    return _opener.open(url, data, timeout)
  File "/usr/lib/python2.7/urllib2.py", line 404, in open
    response = self._open(req, data)
  File "/usr/lib/python2.7/urllib2.py", line 422, in _open
    '_open', req)
  File "/usr/lib/python2.7/urllib2.py", line 382, in _call_chain
    result = func(*args)
  File "/usr/lib/python2.7/urllib2.py", line 1222, in https_open
    return self.do_open(httplib.HTTPSConnection, req)
  File "/usr/lib/python2.7/urllib2.py", line 1184, in do_open
    raise URLError(err)
URLError: <urlopen error [Errno -2] Name or service not known>
2020-02-25 07:05:29,917 INFO https://datos.cdmx.gob.mx/explore/dataset/diagnostico-sobre-la-ciudad-en-el-mundo/download/?format=csv&timezone=America/Mexico_City&lang=es&use_labels_for_header=true&csv_separator=%2C
2020-02-25 07:05:37,117 ERROR 
------------------------------
ERROR
Traceback (most recent call last):
  File "download_files.py", line 30, in download
    filedata = urllib2.urlopen(url)
  File "/usr/lib/python2.7/urllib2.py", line 127, in urlopen
    return _opener.open(url, data, timeout)
  File "/usr/lib/python2.7/urllib2.py", line 404, in open
    response = self._open(req, data)
  File "/usr/lib/python2.7/urllib2.py", line 422, in _open
    '_open', req)
  File "/usr/lib/python2.7/urllib2.py", line 382, in _call_chain
    result = func(*args)
  File "/usr/lib/python2.7/urllib2.py", line 1222, in https_open
    return self.do_open(httplib.HTTPSConnection, req)
  File "/usr/lib/python2.7/urllib2.py", line 1184, in do_open
    raise URLError(err)
URLError: <urlopen error [Errno -2] Name or service not known>
2020-02-25 07:05:37,117 INFO https://datos.cdmx.gob.mx/explore/dataset/incidentes-viales-c5/download/?format=csv&timezone=America/Mexico_City&lang=es&use_labels_for_header=true&csv_separator=%2C
2020-02-25 07:05:44,317 ERROR 
------------------------------
ERROR
Traceback (most recent call last):
  File "download_files.py", line 30, in download
    filedata = urllib2.urlopen(url)
  File "/usr/lib/python2.7/urllib2.py", line 127, in urlopen
    return _opener.open(url, data, timeout)
  File "/usr/lib/python2.7/urllib2.py", line 404, in open
    response = self._open(req, data)
  File "/usr/lib/python2.7/urllib2.py", line 422, in _open
    '_open', req)
  File "/usr/lib/python2.7/urllib2.py", line 382, in _call_chain
    result = func(*args)
  File "/usr/lib/python2.7/urllib2.py", line 1222, in https_open
    return self.do_open(httplib.HTTPSConnection, req)
  File "/usr/lib/python2.7/urllib2.py", line 1184, in do_open
    raise URLError(err)
URLError: <urlopen error [Errno -2] Name or service not known>
2020-02-25 07:05:44,317 INFO https://datos.cdmx.gob.mx/explore/dataset/mapa_ingresos_parquimetros/download/?format=csv&timezone=America/Mexico_City&lang=es&use_labels_for_header=true&csv_separator=%2C
2020-02-25 07:05:48,325 ERROR 
------------------------------
ERROR
Traceback (most recent call last):
  File "download_files.py", line 30, in download
    filedata = urllib2.urlopen(url)
  File "/usr/lib/python2.7/urllib2.py", line 127, in urlopen
    return _opener.open(url, data, timeout)
  File "/usr/lib/python2.7/urllib2.py", line 404, in open
    response = self._open(req, data)
  File "/usr/lib/python2.7/urllib2.py", line 422, in _open
    '_open', req)
  File "/usr/lib/python2.7/urllib2.py", line 382, in _call_chain
    result = func(*args)
  File "/usr/lib/python2.7/urllib2.py", line 1222, in https_open
    return self.do_open(httplib.HTTPSConnection, req)
  File "/usr/lib/python2.7/urllib2.py", line 1184, in do_open
    raise URLError(err)
URLError: <urlopen error [Errno -2] Name or service not known>
2020-02-25 07:05:48,326 INFO https://datos.cdmx.gob.mx/explore/dataset/contador-ciclistas/download/?format=csv&timezone=America/Mexico_City&lang=es&use_labels_for_header=true&csv_separator=%2C
2020-02-25 07:05:49,934 ERROR 
------------------------------
ERROR
Traceback (most recent call last):
  File "download_files.py", line 30, in download
    filedata = urllib2.urlopen(url)
  File "/usr/lib/python2.7/urllib2.py", line 127, in urlopen
    return _opener.open(url, data, timeout)
  File "/usr/lib/python2.7/urllib2.py", line 404, in open
    response = self._open(req, data)
  File "/usr/lib/python2.7/urllib2.py", line 422, in _open
    '_open', req)
  File "/usr/lib/python2.7/urllib2.py", line 382, in _call_chain
    result = func(*args)
  File "/usr/lib/python2.7/urllib2.py", line 1222, in https_open
    return self.do_open(httplib.HTTPSConnection, req)
  File "/usr/lib/python2.7/urllib2.py", line 1184, in do_open
    raise URLError(err)
URLError: <urlopen error [Errno -2] Name or service not known>
2020-02-25 07:05:49,934 INFO https://datos.cdmx.gob.mx/explore/dataset/carpetas-de-investigacion-pgj-de-la-ciudad-de-mexico/download/?format=csv&timezone=America/Mexico_City&lang=es&use_labels_for_header=true&csv_separator=%2C
2020-02-25 07:05:55,229 ERROR 
------------------------------
ERROR
Traceback (most recent call last):
  File "download_files.py", line 30, in download
    filedata = urllib2.urlopen(url)
  File "/usr/lib/python2.7/urllib2.py", line 127, in urlopen
    return _opener.open(url, data, timeout)
  File "/usr/lib/python2.7/urllib2.py", line 404, in open
    response = self._open(req, data)
  File "/usr/lib/python2.7/urllib2.py", line 422, in _open
    '_open', req)
  File "/usr/lib/python2.7/urllib2.py", line 382, in _call_chain
    result = func(*args)
  File "/usr/lib/python2.7/urllib2.py", line 1222, in https_open
    return self.do_open(httplib.HTTPSConnection, req)
  File "/usr/lib/python2.7/urllib2.py", line 1184, in do_open
    raise URLError(err)
URLError: <urlopen error [Errno -2] Name or service not known>
2020-02-25 07:05:55,229 INFO https://datos.cdmx.gob.mx/explore/dataset/victimas-en-carpetas-de-investigacion-pgj/download/?format=csv&timezone=America/Mexico_City&lang=es&use_labels_for_header=true&csv_separator=%2C
2020-02-25 07:05:57,240 ERROR 
------------------------------
ERROR
Traceback (most recent call last):
  File "download_files.py", line 30, in download
    filedata = urllib2.urlopen(url)
  File "/usr/lib/python2.7/urllib2.py", line 127, in urlopen
    return _opener.open(url, data, timeout)
  File "/usr/lib/python2.7/urllib2.py", line 404, in open
    response = self._open(req, data)
  File "/usr/lib/python2.7/urllib2.py", line 422, in _open
    '_open', req)
  File "/usr/lib/python2.7/urllib2.py", line 382, in _call_chain
    result = func(*args)
  File "/usr/lib/python2.7/urllib2.py", line 1222, in https_open
    return self.do_open(httplib.HTTPSConnection, req)
  File "/usr/lib/python2.7/urllib2.py", line 1184, in do_open
    raise URLError(err)
URLError: <urlopen error [Errno -2] Name or service not known>
2020-02-25 07:05:57,240 INFO https://datos.cdmx.gob.mx/explore/dataset/prueba-parquimetros/download/?format=csv&timezone=America/Mexico_City&lang=es&use_labels_for_header=true&csv_separator=%2C
2020-02-25 07:05:57,252 ERROR 
------------------------------
ERROR
Traceback (most recent call last):
  File "download_files.py", line 30, in download
    filedata = urllib2.urlopen(url)
  File "/usr/lib/python2.7/urllib2.py", line 127, in urlopen
    return _opener.open(url, data, timeout)
  File "/usr/lib/python2.7/urllib2.py", line 404, in open
    response = self._open(req, data)
  File "/usr/lib/python2.7/urllib2.py", line 422, in _open
    '_open', req)
  File "/usr/lib/python2.7/urllib2.py", line 382, in _call_chain
    result = func(*args)
  File "/usr/lib/python2.7/urllib2.py", line 1222, in https_open
    return self.do_open(httplib.HTTPSConnection, req)
  File "/usr/lib/python2.7/urllib2.py", line 1184, in do_open
    raise URLError(err)
URLError: <urlopen error [Errno -2] Name or service not known>
2020-02-25 07:05:57,252 INFO https://datos.cdmx.gob.mx/explore/dataset/hechos-de-transito-reportados-por-ssc-base-comparativa/download/?format=csv&timezone=America/Mexico_City&lang=es&use_labels_for_header=true&csv_separator=%2C
2020-02-25 07:06:01,877 ERROR 
------------------------------
ERROR
Traceback (most recent call last):
  File "download_files.py", line 30, in download
    filedata = urllib2.urlopen(url)
  File "/usr/lib/python2.7/urllib2.py", line 127, in urlopen
    return _opener.open(url, data, timeout)
  File "/usr/lib/python2.7/urllib2.py", line 404, in open
    response = self._open(req, data)
  File "/usr/lib/python2.7/urllib2.py", line 422, in _open
    '_open', req)
  File "/usr/lib/python2.7/urllib2.py", line 382, in _call_chain
    result = func(*args)
  File "/usr/lib/python2.7/urllib2.py", line 1222, in https_open
    return self.do_open(httplib.HTTPSConnection, req)
  File "/usr/lib/python2.7/urllib2.py", line 1184, in do_open
    raise URLError(err)
URLError: <urlopen error [Errno -2] Name or service not known>
2020-02-25 07:06:01,877 INFO https://datos.cdmx.gob.mx/explore/dataset/hechos-de-transito-registrados-por-la-ssc-serie-para-comparaciones-interanuales-/download/?format=csv&timezone=America/Mexico_City&lang=es&use_labels_for_header=true&csv_separator=%2C
2020-02-25 07:06:02,266 ERROR 
------------------------------
ERROR
Traceback (most recent call last):
  File "download_files.py", line 30, in download
    filedata = urllib2.urlopen(url)
  File "/usr/lib/python2.7/urllib2.py", line 127, in urlopen
    return _opener.open(url, data, timeout)
  File "/usr/lib/python2.7/urllib2.py", line 404, in open
    response = self._open(req, data)
  File "/usr/lib/python2.7/urllib2.py", line 422, in _open
    '_open', req)
  File "/usr/lib/python2.7/urllib2.py", line 382, in _call_chain
    result = func(*args)
  File "/usr/lib/python2.7/urllib2.py", line 1222, in https_open
    return self.do_open(httplib.HTTPSConnection, req)
  File "/usr/lib/python2.7/urllib2.py", line 1184, in do_open
    raise URLError(err)
URLError: <urlopen error [Errno -2] Name or service not known>
2020-02-25 07:06:02,266 INFO https://datos.cdmx.gob.mx/explore/dataset/gtfs-general-transit-feed-specifications-actualizado-de-la-ciudad-de-mexico/download/?format=csv&timezone=America/Mexico_City&lang=es&use_labels_for_header=true&csv_separator=%2C
2020-02-25 07:06:02,285 ERROR 
------------------------------
ERROR
Traceback (most recent call last):
  File "download_files.py", line 30, in download
    filedata = urllib2.urlopen(url)
  File "/usr/lib/python2.7/urllib2.py", line 127, in urlopen
    return _opener.open(url, data, timeout)
  File "/usr/lib/python2.7/urllib2.py", line 404, in open
    response = self._open(req, data)
  File "/usr/lib/python2.7/urllib2.py", line 422, in _open
    '_open', req)
  File "/usr/lib/python2.7/urllib2.py", line 382, in _call_chain
    result = func(*args)
  File "/usr/lib/python2.7/urllib2.py", line 1222, in https_open
    return self.do_open(httplib.HTTPSConnection, req)
  File "/usr/lib/python2.7/urllib2.py", line 1184, in do_open
    raise URLError(err)
URLError: <urlopen error [Errno -2] Name or service not known>
2020-02-25 07:06:02,286 INFO https://datos.cdmx.gob.mx/explore/dataset/vialidades-de-la-ciudad-de-mexico/download/?format=csv&timezone=America/Mexico_City&lang=es&use_labels_for_header=true&csv_separator=%2C
2020-02-25 07:06:06,294 ERROR 
------------------------------
ERROR
Traceback (most recent call last):
  File "download_files.py", line 30, in download
    filedata = urllib2.urlopen(url)
  File "/usr/lib/python2.7/urllib2.py", line 127, in urlopen
    return _opener.open(url, data, timeout)
  File "/usr/lib/python2.7/urllib2.py", line 404, in open
    response = self._open(req, data)
  File "/usr/lib/python2.7/urllib2.py", line 422, in _open
    '_open', req)
  File "/usr/lib/python2.7/urllib2.py", line 382, in _call_chain
    result = func(*args)
  File "/usr/lib/python2.7/urllib2.py", line 1222, in https_open
    return self.do_open(httplib.HTTPSConnection, req)
  File "/usr/lib/python2.7/urllib2.py", line 1184, in do_open
    raise URLError(err)
URLError: <urlopen error [Errno -2] Name or service not known>
2020-02-25 07:06:06,294 INFO https://datos.cdmx.gob.mx/explore/dataset/ciclovias/download/?format=csv&timezone=America/Mexico_City&lang=es&use_labels_for_header=true&csv_separator=%2C
2020-02-25 07:06:08,281 ERROR 
------------------------------
ERROR
Traceback (most recent call last):
  File "download_files.py", line 30, in download
    filedata = urllib2.urlopen(url)
  File "/usr/lib/python2.7/urllib2.py", line 127, in urlopen
    return _opener.open(url, data, timeout)
  File "/usr/lib/python2.7/urllib2.py", line 404, in open
    response = self._open(req, data)
  File "/usr/lib/python2.7/urllib2.py", line 422, in _open
    '_open', req)
  File "/usr/lib/python2.7/urllib2.py", line 382, in _call_chain
    result = func(*args)
  File "/usr/lib/python2.7/urllib2.py", line 1222, in https_open
    return self.do_open(httplib.HTTPSConnection, req)
  File "/usr/lib/python2.7/urllib2.py", line 1184, in do_open
    raise URLError(err)
URLError: <urlopen error [Errno -2] Name or service not known>
2020-02-25 07:06:08,281 INFO https://datos.cdmx.gob.mx/explore/dataset/estaciones-de-ecobici/download/?format=csv&timezone=America/Mexico_City&lang=es&use_labels_for_header=true&csv_separator=%2C
2020-02-25 07:06:14,552 ERROR 
------------------------------
ERROR
Traceback (most recent call last):
  File "download_files.py", line 30, in download
    filedata = urllib2.urlopen(url)
  File "/usr/lib/python2.7/urllib2.py", line 127, in urlopen
    return _opener.open(url, data, timeout)
  File "/usr/lib/python2.7/urllib2.py", line 404, in open
    response = self._open(req, data)
  File "/usr/lib/python2.7/urllib2.py", line 422, in _open
    '_open', req)
  File "/usr/lib/python2.7/urllib2.py", line 382, in _call_chain
    result = func(*args)
  File "/usr/lib/python2.7/urllib2.py", line 1222, in https_open
    return self.do_open(httplib.HTTPSConnection, req)
  File "/usr/lib/python2.7/urllib2.py", line 1184, in do_open
    raise URLError(err)
URLError: <urlopen error [Errno -2] Name or service not known>
2020-02-25 07:06:14,552 INFO https://publicacionexterna.azurewebsites.net/publicaciones/places
2020-02-25 07:06:15,437 INFO data/cre/places/places.xml
2020-02-25 07:06:15,499 INFO https://publicacionexterna.azurewebsites.net/publicaciones/prices
2020-02-25 07:06:16,155 INFO data/cre/prices/prices.xml
