2021-01-29 08:05:20,648 INFO https://datos.cdmx.gob.mx/explore/dataset/fotocivicas/download/?format=csv&timezone=America/Mexico_City&lang=es&use_labels_for_header=true&csv_separator=%2C
2021-01-29 08:05:21,050 ERROR 
------------------------------
ERROR
Traceback (most recent call last):
  File "download_files.py", line 30, in download
    filedata = urllib2.urlopen(url)
  File "/usr/lib/python2.7/urllib2.py", line 127, in urlopen
    return _opener.open(url, data, timeout)
  File "/usr/lib/python2.7/urllib2.py", line 410, in open
    response = meth(req, response)
  File "/usr/lib/python2.7/urllib2.py", line 523, in http_response
    'http', request, response, code, msg, hdrs)
  File "/usr/lib/python2.7/urllib2.py", line 448, in error
    return self._call_chain(*args)
  File "/usr/lib/python2.7/urllib2.py", line 382, in _call_chain
    result = func(*args)
  File "/usr/lib/python2.7/urllib2.py", line 531, in http_error_default
    raise HTTPError(req.get_full_url(), code, msg, hdrs, fp)
HTTPError: HTTP Error 404: NOT FOUND
2021-01-29 08:05:21,051 INFO https://datos.cdmx.gob.mx/explore/dataset/diagnostico-sobre-la-ciudad-en-el-mundo/download/?format=csv&timezone=America/Mexico_City&lang=es&use_labels_for_header=true&csv_separator=%2C
2021-01-29 08:05:21,391 ERROR 
------------------------------
ERROR
Traceback (most recent call last):
  File "download_files.py", line 30, in download
    filedata = urllib2.urlopen(url)
  File "/usr/lib/python2.7/urllib2.py", line 127, in urlopen
    return _opener.open(url, data, timeout)
  File "/usr/lib/python2.7/urllib2.py", line 410, in open
    response = meth(req, response)
  File "/usr/lib/python2.7/urllib2.py", line 523, in http_response
    'http', request, response, code, msg, hdrs)
  File "/usr/lib/python2.7/urllib2.py", line 448, in error
    return self._call_chain(*args)
  File "/usr/lib/python2.7/urllib2.py", line 382, in _call_chain
    result = func(*args)
  File "/usr/lib/python2.7/urllib2.py", line 531, in http_error_default
    raise HTTPError(req.get_full_url(), code, msg, hdrs, fp)
HTTPError: HTTP Error 404: NOT FOUND
2021-01-29 08:05:21,391 INFO https://datos.cdmx.gob.mx/explore/dataset/incidentes-viales-c5/download/?format=csv&timezone=America/Mexico_City&lang=es&use_labels_for_header=true&csv_separator=%2C
2021-01-29 08:05:21,640 ERROR 
------------------------------
ERROR
Traceback (most recent call last):
  File "download_files.py", line 30, in download
    filedata = urllib2.urlopen(url)
  File "/usr/lib/python2.7/urllib2.py", line 127, in urlopen
    return _opener.open(url, data, timeout)
  File "/usr/lib/python2.7/urllib2.py", line 410, in open
    response = meth(req, response)
  File "/usr/lib/python2.7/urllib2.py", line 523, in http_response
    'http', request, response, code, msg, hdrs)
  File "/usr/lib/python2.7/urllib2.py", line 448, in error
    return self._call_chain(*args)
  File "/usr/lib/python2.7/urllib2.py", line 382, in _call_chain
    result = func(*args)
  File "/usr/lib/python2.7/urllib2.py", line 531, in http_error_default
    raise HTTPError(req.get_full_url(), code, msg, hdrs, fp)
HTTPError: HTTP Error 404: NOT FOUND
2021-01-29 08:05:21,640 INFO https://datos.cdmx.gob.mx/explore/dataset/mapa_ingresos_parquimetros/download/?format=csv&timezone=America/Mexico_City&lang=es&use_labels_for_header=true&csv_separator=%2C
2021-01-29 08:05:21,865 ERROR 
------------------------------
ERROR
Traceback (most recent call last):
  File "download_files.py", line 30, in download
    filedata = urllib2.urlopen(url)
  File "/usr/lib/python2.7/urllib2.py", line 127, in urlopen
    return _opener.open(url, data, timeout)
  File "/usr/lib/python2.7/urllib2.py", line 410, in open
    response = meth(req, response)
  File "/usr/lib/python2.7/urllib2.py", line 523, in http_response
    'http', request, response, code, msg, hdrs)
  File "/usr/lib/python2.7/urllib2.py", line 448, in error
    return self._call_chain(*args)
  File "/usr/lib/python2.7/urllib2.py", line 382, in _call_chain
    result = func(*args)
  File "/usr/lib/python2.7/urllib2.py", line 531, in http_error_default
    raise HTTPError(req.get_full_url(), code, msg, hdrs, fp)
HTTPError: HTTP Error 404: NOT FOUND
2021-01-29 08:05:21,865 INFO https://datos.cdmx.gob.mx/explore/dataset/contador-ciclistas/download/?format=csv&timezone=America/Mexico_City&lang=es&use_labels_for_header=true&csv_separator=%2C
2021-01-29 08:05:22,117 ERROR 
------------------------------
ERROR
Traceback (most recent call last):
  File "download_files.py", line 30, in download
    filedata = urllib2.urlopen(url)
  File "/usr/lib/python2.7/urllib2.py", line 127, in urlopen
    return _opener.open(url, data, timeout)
  File "/usr/lib/python2.7/urllib2.py", line 410, in open
    response = meth(req, response)
  File "/usr/lib/python2.7/urllib2.py", line 523, in http_response
    'http', request, response, code, msg, hdrs)
  File "/usr/lib/python2.7/urllib2.py", line 448, in error
    return self._call_chain(*args)
  File "/usr/lib/python2.7/urllib2.py", line 382, in _call_chain
    result = func(*args)
  File "/usr/lib/python2.7/urllib2.py", line 531, in http_error_default
    raise HTTPError(req.get_full_url(), code, msg, hdrs, fp)
HTTPError: HTTP Error 404: NOT FOUND
2021-01-29 08:05:22,117 INFO https://datos.cdmx.gob.mx/explore/dataset/carpetas-de-investigacion-pgj-de-la-ciudad-de-mexico/download/?format=csv&timezone=America/Mexico_City&lang=es&use_labels_for_header=true&csv_separator=%2C
2021-01-29 08:05:22,349 ERROR 
------------------------------
ERROR
Traceback (most recent call last):
  File "download_files.py", line 30, in download
    filedata = urllib2.urlopen(url)
  File "/usr/lib/python2.7/urllib2.py", line 127, in urlopen
    return _opener.open(url, data, timeout)
  File "/usr/lib/python2.7/urllib2.py", line 410, in open
    response = meth(req, response)
  File "/usr/lib/python2.7/urllib2.py", line 523, in http_response
    'http', request, response, code, msg, hdrs)
  File "/usr/lib/python2.7/urllib2.py", line 448, in error
    return self._call_chain(*args)
  File "/usr/lib/python2.7/urllib2.py", line 382, in _call_chain
    result = func(*args)
  File "/usr/lib/python2.7/urllib2.py", line 531, in http_error_default
    raise HTTPError(req.get_full_url(), code, msg, hdrs, fp)
HTTPError: HTTP Error 404: NOT FOUND
2021-01-29 08:05:22,350 INFO https://datos.cdmx.gob.mx/explore/dataset/victimas-en-carpetas-de-investigacion-pgj/download/?format=csv&timezone=America/Mexico_City&lang=es&use_labels_for_header=true&csv_separator=%2C
2021-01-29 08:05:22,600 ERROR 
------------------------------
ERROR
Traceback (most recent call last):
  File "download_files.py", line 30, in download
    filedata = urllib2.urlopen(url)
  File "/usr/lib/python2.7/urllib2.py", line 127, in urlopen
    return _opener.open(url, data, timeout)
  File "/usr/lib/python2.7/urllib2.py", line 410, in open
    response = meth(req, response)
  File "/usr/lib/python2.7/urllib2.py", line 523, in http_response
    'http', request, response, code, msg, hdrs)
  File "/usr/lib/python2.7/urllib2.py", line 448, in error
    return self._call_chain(*args)
  File "/usr/lib/python2.7/urllib2.py", line 382, in _call_chain
    result = func(*args)
  File "/usr/lib/python2.7/urllib2.py", line 531, in http_error_default
    raise HTTPError(req.get_full_url(), code, msg, hdrs, fp)
HTTPError: HTTP Error 404: NOT FOUND
2021-01-29 08:05:22,600 INFO https://datos.cdmx.gob.mx/explore/dataset/prueba-parquimetros/download/?format=csv&timezone=America/Mexico_City&lang=es&use_labels_for_header=true&csv_separator=%2C
2021-01-29 08:05:22,823 ERROR 
------------------------------
ERROR
Traceback (most recent call last):
  File "download_files.py", line 30, in download
    filedata = urllib2.urlopen(url)
  File "/usr/lib/python2.7/urllib2.py", line 127, in urlopen
    return _opener.open(url, data, timeout)
  File "/usr/lib/python2.7/urllib2.py", line 410, in open
    response = meth(req, response)
  File "/usr/lib/python2.7/urllib2.py", line 523, in http_response
    'http', request, response, code, msg, hdrs)
  File "/usr/lib/python2.7/urllib2.py", line 448, in error
    return self._call_chain(*args)
  File "/usr/lib/python2.7/urllib2.py", line 382, in _call_chain
    result = func(*args)
  File "/usr/lib/python2.7/urllib2.py", line 531, in http_error_default
    raise HTTPError(req.get_full_url(), code, msg, hdrs, fp)
HTTPError: HTTP Error 404: NOT FOUND
2021-01-29 08:05:22,823 INFO https://datos.cdmx.gob.mx/explore/dataset/hechos-de-transito-reportados-por-ssc-base-comparativa/download/?format=csv&timezone=America/Mexico_City&lang=es&use_labels_for_header=true&csv_separator=%2C
2021-01-29 08:05:23,076 ERROR 
------------------------------
ERROR
Traceback (most recent call last):
  File "download_files.py", line 30, in download
    filedata = urllib2.urlopen(url)
  File "/usr/lib/python2.7/urllib2.py", line 127, in urlopen
    return _opener.open(url, data, timeout)
  File "/usr/lib/python2.7/urllib2.py", line 410, in open
    response = meth(req, response)
  File "/usr/lib/python2.7/urllib2.py", line 523, in http_response
    'http', request, response, code, msg, hdrs)
  File "/usr/lib/python2.7/urllib2.py", line 448, in error
    return self._call_chain(*args)
  File "/usr/lib/python2.7/urllib2.py", line 382, in _call_chain
    result = func(*args)
  File "/usr/lib/python2.7/urllib2.py", line 531, in http_error_default
    raise HTTPError(req.get_full_url(), code, msg, hdrs, fp)
HTTPError: HTTP Error 404: NOT FOUND
2021-01-29 08:05:23,076 INFO https://datos.cdmx.gob.mx/explore/dataset/hechos-de-transito-registrados-por-la-ssc-serie-para-comparaciones-interanuales-/download/?format=csv&timezone=America/Mexico_City&lang=es&use_labels_for_header=true&csv_separator=%2C
2021-01-29 08:05:23,306 ERROR 
------------------------------
ERROR
Traceback (most recent call last):
  File "download_files.py", line 30, in download
    filedata = urllib2.urlopen(url)
  File "/usr/lib/python2.7/urllib2.py", line 127, in urlopen
    return _opener.open(url, data, timeout)
  File "/usr/lib/python2.7/urllib2.py", line 410, in open
    response = meth(req, response)
  File "/usr/lib/python2.7/urllib2.py", line 523, in http_response
    'http', request, response, code, msg, hdrs)
  File "/usr/lib/python2.7/urllib2.py", line 448, in error
    return self._call_chain(*args)
  File "/usr/lib/python2.7/urllib2.py", line 382, in _call_chain
    result = func(*args)
  File "/usr/lib/python2.7/urllib2.py", line 531, in http_error_default
    raise HTTPError(req.get_full_url(), code, msg, hdrs, fp)
HTTPError: HTTP Error 404: NOT FOUND
2021-01-29 08:05:23,306 INFO https://datos.cdmx.gob.mx/explore/dataset/gtfs-general-transit-feed-specifications-actualizado-de-la-ciudad-de-mexico/download/?format=csv&timezone=America/Mexico_City&lang=es&use_labels_for_header=true&csv_separator=%2C
2021-01-29 08:05:23,560 ERROR 
------------------------------
ERROR
Traceback (most recent call last):
  File "download_files.py", line 30, in download
    filedata = urllib2.urlopen(url)
  File "/usr/lib/python2.7/urllib2.py", line 127, in urlopen
    return _opener.open(url, data, timeout)
  File "/usr/lib/python2.7/urllib2.py", line 410, in open
    response = meth(req, response)
  File "/usr/lib/python2.7/urllib2.py", line 523, in http_response
    'http', request, response, code, msg, hdrs)
  File "/usr/lib/python2.7/urllib2.py", line 448, in error
    return self._call_chain(*args)
  File "/usr/lib/python2.7/urllib2.py", line 382, in _call_chain
    result = func(*args)
  File "/usr/lib/python2.7/urllib2.py", line 531, in http_error_default
    raise HTTPError(req.get_full_url(), code, msg, hdrs, fp)
HTTPError: HTTP Error 404: NOT FOUND
2021-01-29 08:05:23,560 INFO https://datos.cdmx.gob.mx/explore/dataset/vialidades-de-la-ciudad-de-mexico/download/?format=csv&timezone=America/Mexico_City&lang=es&use_labels_for_header=true&csv_separator=%2C
2021-01-29 08:05:23,852 ERROR 
------------------------------
ERROR
Traceback (most recent call last):
  File "download_files.py", line 30, in download
    filedata = urllib2.urlopen(url)
  File "/usr/lib/python2.7/urllib2.py", line 127, in urlopen
    return _opener.open(url, data, timeout)
  File "/usr/lib/python2.7/urllib2.py", line 410, in open
    response = meth(req, response)
  File "/usr/lib/python2.7/urllib2.py", line 523, in http_response
    'http', request, response, code, msg, hdrs)
  File "/usr/lib/python2.7/urllib2.py", line 448, in error
    return self._call_chain(*args)
  File "/usr/lib/python2.7/urllib2.py", line 382, in _call_chain
    result = func(*args)
  File "/usr/lib/python2.7/urllib2.py", line 531, in http_error_default
    raise HTTPError(req.get_full_url(), code, msg, hdrs, fp)
HTTPError: HTTP Error 404: NOT FOUND
2021-01-29 08:05:23,852 INFO https://datos.cdmx.gob.mx/explore/dataset/ciclovias/download/?format=csv&timezone=America/Mexico_City&lang=es&use_labels_for_header=true&csv_separator=%2C
2021-01-29 08:05:24,122 ERROR 
------------------------------
ERROR
Traceback (most recent call last):
  File "download_files.py", line 30, in download
    filedata = urllib2.urlopen(url)
  File "/usr/lib/python2.7/urllib2.py", line 127, in urlopen
    return _opener.open(url, data, timeout)
  File "/usr/lib/python2.7/urllib2.py", line 410, in open
    response = meth(req, response)
  File "/usr/lib/python2.7/urllib2.py", line 523, in http_response
    'http', request, response, code, msg, hdrs)
  File "/usr/lib/python2.7/urllib2.py", line 448, in error
    return self._call_chain(*args)
  File "/usr/lib/python2.7/urllib2.py", line 382, in _call_chain
    result = func(*args)
  File "/usr/lib/python2.7/urllib2.py", line 531, in http_error_default
    raise HTTPError(req.get_full_url(), code, msg, hdrs, fp)
HTTPError: HTTP Error 404: NOT FOUND
2021-01-29 08:05:24,122 INFO https://datos.cdmx.gob.mx/explore/dataset/estaciones-de-ecobici/download/?format=csv&timezone=America/Mexico_City&lang=es&use_labels_for_header=true&csv_separator=%2C
2021-01-29 08:05:24,366 ERROR 
------------------------------
ERROR
Traceback (most recent call last):
  File "download_files.py", line 30, in download
    filedata = urllib2.urlopen(url)
  File "/usr/lib/python2.7/urllib2.py", line 127, in urlopen
    return _opener.open(url, data, timeout)
  File "/usr/lib/python2.7/urllib2.py", line 410, in open
    response = meth(req, response)
  File "/usr/lib/python2.7/urllib2.py", line 523, in http_response
    'http', request, response, code, msg, hdrs)
  File "/usr/lib/python2.7/urllib2.py", line 448, in error
    return self._call_chain(*args)
  File "/usr/lib/python2.7/urllib2.py", line 382, in _call_chain
    result = func(*args)
  File "/usr/lib/python2.7/urllib2.py", line 531, in http_error_default
    raise HTTPError(req.get_full_url(), code, msg, hdrs, fp)
HTTPError: HTTP Error 404: NOT FOUND
2021-01-29 08:05:24,366 INFO https://datos.cdmx.gob.mx/explore/dataset/base-covid-sinave/download/?format=csv&timezone=America/Mexico_City&lang=es&use_labels_for_header=true&csv_separator=%2C
2021-01-29 08:05:24,625 ERROR 
------------------------------
ERROR
Traceback (most recent call last):
  File "download_files.py", line 30, in download
    filedata = urllib2.urlopen(url)
  File "/usr/lib/python2.7/urllib2.py", line 127, in urlopen
    return _opener.open(url, data, timeout)
  File "/usr/lib/python2.7/urllib2.py", line 410, in open
    response = meth(req, response)
  File "/usr/lib/python2.7/urllib2.py", line 523, in http_response
    'http', request, response, code, msg, hdrs)
  File "/usr/lib/python2.7/urllib2.py", line 448, in error
    return self._call_chain(*args)
  File "/usr/lib/python2.7/urllib2.py", line 382, in _call_chain
    result = func(*args)
  File "/usr/lib/python2.7/urllib2.py", line 531, in http_error_default
    raise HTTPError(req.get_full_url(), code, msg, hdrs, fp)
HTTPError: HTTP Error 404: NOT FOUND
2021-01-29 08:05:24,625 INFO http://187.191.75.115/gobmx/salud/datos_abiertos/datos_abiertos_covid19.zip
2021-01-29 08:07:35,510 ERROR 
------------------------------
ERROR
Traceback (most recent call last):
  File "download_files.py", line 30, in download
    filedata = urllib2.urlopen(url)
  File "/usr/lib/python2.7/urllib2.py", line 127, in urlopen
    return _opener.open(url, data, timeout)
  File "/usr/lib/python2.7/urllib2.py", line 404, in open
    response = self._open(req, data)
  File "/usr/lib/python2.7/urllib2.py", line 422, in _open
    '_open', req)
  File "/usr/lib/python2.7/urllib2.py", line 382, in _call_chain
    result = func(*args)
  File "/usr/lib/python2.7/urllib2.py", line 1214, in http_open
    return self.do_open(httplib.HTTPConnection, req)
  File "/usr/lib/python2.7/urllib2.py", line 1184, in do_open
    raise URLError(err)
URLError: <urlopen error [Errno 110] Connection timed out>
2021-01-29 08:07:35,510 INFO https://publicacionexterna.azurewebsites.net/publicaciones/places
2021-01-29 08:07:36,769 INFO data/cre/places/places.xml
2021-01-29 08:07:36,783 INFO https://publicacionexterna.azurewebsites.net/publicaciones/prices
2021-01-29 08:07:37,443 INFO data/cre/prices/prices.xml
